<mujoco model="R2">
  <compiler angle="radian" meshdir="meshes/"/>
  <statistic meansize="0.144785" extent="1.23314" center="0.025392 2.0634e-05 -0.245975"/>
  <default>   
    <geom condim='4' contype="1" conaffinity="15" solref='0.001 2' friction='0.9 0.2 0.2'/>
    <joint damping="0.01" armature="0.01" frictionloss="0.01" limited='true'/>
  </default>

  <asset>
    <mesh name="base_link" file="base_link.STL"/>
    <mesh name="left_hip_pitch_link" file="left_hip_pitch_link.STL"/>
    <mesh name="left_hip_roll_link" file="left_hip_roll_link.STL"/>
    <mesh name="left_hip_yaw_link" file="left_hip_yaw_link.STL"/>
    <mesh name="left_knee_pitch_link" file="left_knee_pitch_link.STL"/>
    <mesh name="left_ankle_pitch_link" file="left_ankle_pitch_link.STL"/>
    <mesh name="left_ankle_roll_link" file="left_ankle_roll_link.STL"/>
    <mesh name="right_hip_pitch_link" file="right_hip_pitch_link.STL"/>
    <mesh name="right_hip_roll_link" file="right_hip_roll_link.STL"/>
    <mesh name="right_hip_yaw_link" file="right_hip_yaw_link.STL"/>
    <mesh name="right_knee_pitch_link" file="right_knee_pitch_link.STL"/>
    <mesh name="right_ankle_pitch_link" file="right_ankle_pitch_link.STL"/>
    <mesh name="right_ankle_roll_link" file="right_ankle_roll_link.STL"/>
    <mesh name="waist_yaw_link" file="waist_yaw_link.STL"/>
    <mesh name="waist_pitch_link" file="waist_pitch_link.STL"/>
    <mesh name="left_shoulder_pitch_link" file="left_shoulder_pitch_link.STL"/>
    <mesh name="left_shoulder_roll_link" file="left_shoulder_roll_link.STL"/>
    <mesh name="left_shoulder_yaw_link" file="left_shoulder_yaw_link.STL"/>
    <mesh name="left_arm_pitch_link" file="left_arm_pitch_link.STL"/>
    <mesh name="right_shoulder_pitch_link" file="right_shoulder_pitch_link.STL"/>
    <mesh name="right_shoulder_roll_link" file="right_shoulder_roll_link.STL"/>
    <mesh name="right_shoulder_yaw_link" file="right_shoulder_yaw_link.STL"/>
    <mesh name="right_arm_pitch_link" file="right_arm_pitch_link.STL"/>

    <texture type="skybox" builtin="flat" rgb1="0 0 0" rgb2="0 0 0" width="512" height="3072"/>
    <texture type="2d" name="groundplane" builtin="checker" mark="edge" rgb1="0.2 0.3 0.4" rgb2="0.1 0.2 0.3" markrgb="0.8 0.8 0.8" width="300" height="300"/>
    <material name="groundplane" texture="groundplane" texuniform="true" texrepeat="5 5" reflectance="0.2"/>
  </asset>

  <worldbody>
    <light pos="1 0 3.5" dir="0 0 -1" directional="true"/>
    <geom name="floor" size="0 0 0.05" type="plane" material="groundplane"/>
    <body name="base_link" pos="0.0 0.0 0.665">
      <inertial pos="0.00376269 -0.00021695 0.0307689" quat="0.999916 0.00249636 0.0126979 0.000746694" mass="3.44811" diaginertia="0.0129519 0.0114087 0.00619498"/>
      <joint name="floating_base_joint" type="free" limited="false"/>
      <site name='imu_in_base' size='0.01' pos='0.0059965 -0.003397 -0.070175'/>

      <geom type="mesh" contype="0" conaffinity="0" group="1" density="0" rgba="0.69804 0.69804 0.69804 1" mesh="base_link"/>
      <geom type="mesh" rgba="0.69804 0.69804 0.69804 1" mesh="base_link"/>
      <body name="left_hip_pitch_link" pos="0 0.05845 0">
        <inertial pos="0.00030248 0.0537464 0.00090299" quat="0.563134 0.809721 -0.0785028 0.145156" mass="1.27" diaginertia="0.00207689 0.00134952 0.00125886"/>
        <joint name="left_hip_pitch_joint" pos="0 0 0" axis="0 1 0" range="-2.8798 2.4435"/>
        <geom type="mesh" contype="0" conaffinity="0" group="1" density="0" rgba="0.698039 0.698039 0.698039 1" mesh="left_hip_pitch_link"/>
        <!-- <geom type="mesh" rgba="0.698039 0.698039 0.698039 1" mesh="left_hip_pitch_link"/> -->
        <body name="left_hip_roll_link" pos="0.0249723 0.0615 0.00908931" quat="0.984808 0 -0.173648 0">
          <inertial pos="-0.00825674 -8.02e-06 -0.0660066" quat="0.979876 0.00280785 0.199242 0.0117178" mass="1.41" diaginertia="0.00361708 0.00342565 0.00131424"/>
          <joint name="left_hip_roll_joint" pos="0 0 0" axis="1 0 0" range="-0.2618 2.4435"/>
          <geom type="mesh" contype="0" conaffinity="0" group="1" density="0" rgba="0.698039 0.698039 0.698039 1" mesh="left_hip_roll_link"/>
          <!-- <geom type="mesh" rgba="0.698039 0.698039 0.698039 1" mesh="left_hip_roll_link"/> -->
          <body name="left_hip_yaw_link" pos="-0.02675 0 -0.1225">
            <inertial pos="-0.0340875 4.708e-05 -0.134634" quat="0.686821 0.14227 0.140777 0.698726" mass="2.36" diaginertia="0.0124017 0.0103408 0.00274142"/>
            <joint name="left_hip_yaw_joint" pos="0 0 0" axis="0 0 1" range="-2.7576 2.7576"/>
            <geom type="mesh" contype="0" conaffinity="0" group="1" density="0" rgba="0.698039 0.698039 0.698039 1" mesh="left_hip_yaw_link"/>
            <!-- <geom type="mesh" rgba="0.698039 0.698039 0.698039 1" mesh="left_hip_yaw_link"/> -->
            <body name="left_knee_link" pos="-0.066694 0.02125 -0.18724" quat="0.984807 0 0.17365 0">
              <inertial pos="0.0023069 -0.0152341 -0.143518" quat="0.976967 -0.0441442 0.0136726 0.208327" mass="1.81" diaginertia="0.00710137 0.00705459 0.000547486"/>
              <joint name="left_knee_joint" pos="0 0 0" axis="0 1 0" range="-0.40143 2.4435"/>
              <geom type="mesh" contype="0" conaffinity="0" group="1" density="0" rgba="0.698039 0.698039 0.698039 1" mesh="left_knee_pitch_link"/>
              <!-- <geom type="mesh" rgba="0.698039 0.698039 0.698039 1" mesh="left_knee_pitch_link"/> -->
              <body name="left_ankle_pitch_link" pos="0.00014288 -0.02125 -0.298" quat="1 0 -0.000239735 0">
                <inertial pos="-0.00174962 0 -0.0115014" quat="0.601391 0.371926 0.371926 0.601391" mass="0.096984" diaginertia="2.495e-05 1.6474e-05 1.3096e-05"/>
                <joint name="left_ankle_pitch_joint" pos="0 0 0" axis="0 1 0" range="-0.69813 0.5236"/>
                <geom type="mesh" contype="0" conaffinity="0" group="1" density="0" rgba="0.752941 0.752941 0.752941 1" mesh="left_ankle_pitch_link"/>
                <!-- <geom type="mesh" rgba="0.752941 0.752941 0.752941 1" mesh="left_ankle_pitch_link"/> -->
                <body name="left_ankle_roll_link" pos="0 0 -0.02">
                  <inertial pos="0.0106183 9.74e-06 -0.0116145" quat="0.000227447 0.731737 0.000395801 0.681587" mass="0.54" diaginertia="0.00111582 0.00102762 0.000224573"/>
                  <joint name="left_ankle_roll_joint" pos="0 0 0" axis="1 0 0" range="-0.2618 0.2618"/>
                  <geom type="mesh" contype="0" conaffinity="0" group="1" density="0" rgba="0.698039 0.698039 0.698039 1" mesh="left_ankle_roll_link"/>
                  <geom size="0.005" pos="-0.05 0.025 -0.025" rgba="0.698039 0.698039 0.698039 1"/>
                  <geom size="0.005" pos="-0.05 -0.025 -0.025" rgba="0.698039 0.698039 0.698039 1"/>
                  <geom size="0.005" pos="0.12 0.03 -0.025" rgba="0.698039 0.698039 0.698039 1"/>
                  <geom size="0.005" pos="0.12 -0.03 -0.025" rgba="0.698039 0.698039 0.698039 1"/>
                </body>
              </body>
            </body>
          </body>
        </body>
      </body>
      <body name="right_hip_pitch_link" pos="0 -0.05845 0">
        <inertial pos="0.00054486 -0.0535021 0.00123519" quat="0.821018 0.547942 -0.141283 0.0756818" mass="1.27" diaginertia="0.00209204 0.00136627 0.0012822"/>
        <joint name="right_hip_pitch_joint" pos="0 0 0" axis="0 1 0" range="-2.8798 2.4435"/>
        <geom type="mesh" contype="0" conaffinity="0" group="1" density="0" rgba="0.698039 0.698039 0.698039 1" mesh="right_hip_pitch_link"/>
        <!-- <geom type="mesh" rgba="0.698039 0.698039 0.698039 1" mesh="right_hip_pitch_link"/> -->
        <body name="right_hip_roll_link" pos="0.0249724 -0.0611 0.00908906" quat="0.984808 0 -0.173648 0">
          <inertial pos="-0.00825674 -8.02e-06 -0.0660066" quat="0.979876 0.00280785 0.199242 0.0117178" mass="1.41" diaginertia="0.00361708 0.00342565 0.00131424"/>
          <joint name="right_hip_roll_joint" pos="0 0 0" axis="1 0 0" range="-2.4435 0.2618"/>
          <geom type="mesh" contype="0" conaffinity="0" group="1" density="0" rgba="0.698039 0.698039 0.698039 1" mesh="right_hip_roll_link"/>
          <!-- <geom type="mesh" rgba="0.698039 0.698039 0.698039 1" mesh="right_hip_roll_link"/> -->
          <body name="right_hip_yaw_link" pos="-0.02675 0 -0.1225">
            <inertial pos="-0.0340966 -4.62e-05 -0.134631" quat="0.698759 0.140849 0.142375 0.686751" mass="2.36" diaginertia="0.0124021 0.010341 0.0027416"/>
            <joint name="right_hip_yaw_joint" pos="0 0 0" axis="0 0 1" range="-2.7576 2.7576"/>
            <geom type="mesh" contype="0" conaffinity="0" group="1" density="0" rgba="0.698039 0.698039 0.698039 1" mesh="right_hip_yaw_link"/>
            <!-- <geom type="mesh" rgba="0.698039 0.698039 0.698039 1" mesh="right_hip_yaw_link"/> -->
            <body name="right_knee_link" pos="-0.066694 -0.02125 -0.18724" quat="0.984807 0 0.17365 0">
              <inertial pos="0.00230569 0.0152405 -0.143518" quat="0.976913 0.0441404 0.01369 -0.20858" mass="1.81" diaginertia="0.00710109 0.00705415 0.000547556"/>
              <joint name="right_knee_joint" pos="0 0 0" axis="0 1 0" range="-0.40143 2.4435"/>
              <geom type="mesh" contype="0" conaffinity="0" group="1" density="0" rgba="0.698039 0.698039 0.698039 1" mesh="right_knee_pitch_link"/>
              <!-- <geom type="mesh" rgba="0.698039 0.698039 0.698039 1" mesh="right_knee_pitch_link"/> -->
              <body name="right_ankle_pitch_link" pos="0.000142882 0.02125 -0.298" quat="1 0 -0.000239736 0">
                <inertial pos="-0.00174962 0 -0.0115014" quat="0.601391 0.371926 0.371926 0.601391" mass="0.096984" diaginertia="2.495e-05 1.6474e-05 1.3096e-05"/>
                <joint name="right_ankle_pitch_joint" pos="0 0 0" axis="0 1 0" range="-0.69813 0.5236"/>
                <geom type="mesh" contype="0" conaffinity="0" group="1" density="0" rgba="0.752941 0.752941 0.752941 1" mesh="right_ankle_pitch_link"/>
                <!-- <geom type="mesh" rgba="0.752941 0.752941 0.752941 1" mesh="right_ankle_pitch_link"/> -->
                <body name="right_ankle_roll_link" pos="0 0 -0.02">
                  <inertial pos="0.0107026 1.301e-05 -0.011659" quat="0.000132409 0.731371 0.000218251 0.68198" mass="0.54" diaginertia="0.00111362 0.00102501 0.000224146"/>
                  <joint name="right_ankle_roll_joint" pos="0 0 0" axis="1 0 0" range="-0.2618 0.2618"/>
                  <geom type="mesh" contype="0" conaffinity="0" group="1" density="0" rgba="0.698039 0.698039 0.698039 1" mesh="right_ankle_roll_link"/>
                  <geom size="0.005" pos="-0.05 0.025 -0.025" rgba="0.698039 0.698039 0.698039 1"/>
                  <geom size="0.005" pos="-0.05 -0.025 -0.025" rgba="0.698039 0.698039 0.698039 1"/>
                  <geom size="0.005" pos="0.12 0.03 -0.025" rgba="0.698039 0.698039 0.698039 1"/>
                  <geom size="0.005" pos="0.12 -0.03 -0.025" rgba="0.698039 0.698039 0.698039 1"/>
                </body>
              </body>
            </body>
          </body>
        </body>
      </body>
      <body name="waist_yaw_link" pos="0 0 0.1227">
        <inertial pos="-0.00017132 0.00527274 0.0548433" quat="0.706705 0.001901 0.0463467 0.705986" mass="1.2628" diaginertia="0.00201434 0.00144558 0.00134748"/>
        <!-- <joint name="waist_yaw_joint" pos="0 0 0" axis="0 0 1" range="-0.5236 0.5236" actuatorfrcrange="-90 90"/> -->
        <geom type="mesh" contype="0" conaffinity="0" group="1" density="0" rgba="1 1 1 1" mesh="waist_yaw_link"/>
        <!-- <geom type="mesh" rgba="1 1 1 1" mesh="waist_yaw_link"/> -->
        <body name="waist_pitch_link" pos="0 0 0.0615">
          <inertial pos="0.00200153 0.00012059 0.183422" quat="0.99993 0.00248594 -0.0115851 0.00039702" mass="11.55" diaginertia="0.169601 0.149318 0.0866399"/>
          <!-- <joint name="waist_pitch_joint" pos="0 0 0" axis="0 1 0" range="-0.5236 0.5236" actuatorfrcrange="-90 90"/> -->
          <geom type="mesh" contype="0" conaffinity="0" group="1" density="0" rgba="0.698039 0.698039 0.698039 1" mesh="waist_pitch_link"/>
          <!-- <geom type="mesh" rgba="0.698039 0.698039 0.698039 1" mesh="waist_pitch_link"/> -->
          <body name="left_shoulder_pitch_link" pos="0 0.155 0.318">
            <inertial pos="-0.00451131 -0.00478488 1.554e-05" quat="-0.188711 0.637288 -0.308822 0.680354" mass="0.520078" diaginertia="0.000363384 0.000361361 0.000301695"/>
            <!-- <joint name="left_shoulder_pitch_joint" pos="0 0 0" axis="0 1 0" range="-3.0892 2.6704" actuatorfrcrange="-36 36"/> -->
            <geom type="mesh" contype="0" conaffinity="0" group="1" density="0" rgba="0.698039 0.698039 0.698039 1" mesh="left_shoulder_pitch_link"/>
            <geom type="mesh" rgba="0.698039 0.698039 0.698039 1" mesh="left_shoulder_pitch_link"/>
            <body name="left_shoulder_roll_link">
              <inertial pos="0.0219639 0.00026962 -0.0372916" quat="0.991118 0.00114243 0.132847 -0.00593672" mass="0.0861375" diaginertia="8.67388e-05 8.37505e-05 2.14307e-05"/>
              <!-- <joint name="left_shoulder_roll_joint" pos="0 0 0" axis="1 0 0" range="-0.5236 2.2427" actuatorfrcrange="-36 36"/> -->
              <geom type="mesh" contype="0" conaffinity="0" group="1" density="0" rgba="0.698039 0.698039 0.698039 1" mesh="left_shoulder_roll_link"/>
              <geom type="mesh" rgba="0.698039 0.698039 0.698039 1" mesh="left_shoulder_roll_link"/>
              <body name="left_shoulder_yaw_link" pos="-0.0005 0 -0.07">
                <inertial pos="0.00284706 0.00028813 -0.0729803" quat="0.996358 0.00256516 -0.0851444 0.00368657" mass="1.03229" diaginertia="0.00250189 0.00247361 0.000653131"/>
                <!-- <joint name="left_shoulder_yaw_joint" pos="0 0 0" axis="0 0 1" range="-2.618 2.618" actuatorfrcrange="-36 36"/> -->
                <geom type="mesh" contype="0" conaffinity="0" group="1" density="0" rgba="0.698039 0.698039 0.698039 1" mesh="left_shoulder_yaw_link"/>
                <geom type="mesh" rgba="0.698039 0.698039 0.698039 1" mesh="left_shoulder_yaw_link"/>
                <body name="left_arm_pitch_link" pos="0.015 0.03175 -0.115">
                  <inertial pos="0.087202 -0.0154517 -0.00739993" quat="-0.0476934 0.699825 -0.144893 0.697837" mass="0.133013" diaginertia="0.000917379 0.000912899 4.13617e-05"/>
                  <!-- <joint name="left_arm_pitch_joint" pos="0 0 0" axis="0 1 0" range="-1.0472 2.0944" actuatorfrcrange="-36 36"/> -->
                  <geom type="mesh" contype="0" conaffinity="0" group="1" density="0" rgba="0.698039 0.698039 0.698039 1" mesh="left_arm_pitch_link"/>
                  <geom type="mesh" rgba="0.698039 0.698039 0.698039 1" mesh="left_arm_pitch_link"/>
                </body>
              </body>
            </body>
          </body>
          <body name="right_shoulder_pitch_link" pos="0 -0.155 0.318">
            <inertial pos="-0.00451131 0.00478518 2.441e-05" quat="0.109797 0.665096 0.232223 0.701188" mass="0.520078" diaginertia="0.000362607 0.00036214 0.000301693"/>
            <!-- <joint name="right_shoulder_pitch_joint" pos="0 0 0" axis="0 1 0" range="-3.0892 2.6704" actuatorfrcrange="-36 36"/> -->
            <geom type="mesh" contype="0" conaffinity="0" group="1" density="0" rgba="0.698039 0.698039 0.698039 1" mesh="right_shoulder_pitch_link"/>
            <geom type="mesh" rgba="0.698039 0.698039 0.698039 1" mesh="right_shoulder_pitch_link"/>
            <body name="right_shoulder_roll_link">
              <inertial pos="0.0219639 -0.00026963 -0.0372916" quat="0.991118 -0.00114243 0.132847 0.00593672" mass="0.0861375" diaginertia="8.67388e-05 8.37505e-05 2.14307e-05"/>
              <!-- <joint name="right_shoulder_roll_joint" pos="0 0 0" axis="1 0 0" range="-2.2427 0.5236" actuatorfrcrange="-36 36"/> -->
              <geom type="mesh" contype="0" conaffinity="0" group="1" density="0" rgba="0.698039 0.698039 0.698039 1" mesh="right_shoulder_roll_link"/>
              <geom type="mesh" rgba="0.698039 0.698039 0.698039 1" mesh="right_shoulder_roll_link"/>
              <body name="right_shoulder_yaw_link" pos="-0.0005 0 -0.07">
                <inertial pos="0.00284669 -0.00027136 -0.0729633" quat="0.996352 -0.00266917 -0.0851626 -0.00481985" mass="1.03229" diaginertia="0.00250041 0.00247213 0.000653137"/>
                <!-- <joint name="right_shoulder_yaw_joint" pos="0 0 0" axis="0 0 1" range="-2.618 2.618" actuatorfrcrange="-36 36"/> -->
                <geom type="mesh" contype="0" conaffinity="0" group="1" density="0" rgba="0.698039 0.698039 0.698039 1" mesh="right_shoulder_yaw_link"/>
                <geom type="mesh" rgba="0.698039 0.698039 0.698039 1" mesh="right_shoulder_yaw_link"/>
                <body name="right_arm_pitch_link" pos="0.015 -0.03175 -0.115">
                  <inertial pos="0.0872009 0.0154517 -0.00740098" quat="0.0487992 0.699595 0.146 0.69776" mass="0.133013" diaginertia="0.000917419 0.000912909 4.13619e-05"/>
                  <!-- <joint name="right_arm_pitch_joint" pos="0 0 0" axis="0 1 0" range="-1.0472 2.0944" actuatorfrcrange="-36 36"/> -->
                  <geom type="mesh" contype="0" conaffinity="0" group="1" density="0" rgba="0.698039 0.698039 0.698039 1" mesh="right_arm_pitch_link"/>
                  <geom type="mesh" rgba="0.698039 0.698039 0.698039 1" mesh="right_arm_pitch_link"/>
                </body>
              </body>
            </body>
          </body>
        </body>
      </body>
    </body>
  </worldbody>
  <actuator>
    <motor name="left_hip_pitch_joint" joint="left_hip_pitch_joint" gear="1" ctrllimited="true" ctrlrange="-130 130"/>
    <motor name="left_hip_roll_joint" joint="left_hip_roll_joint" gear="1" ctrllimited="true" ctrlrange="-130 130"/>
    <motor name="left_hip_yaw_joint" joint="left_hip_yaw_joint" gear="1" ctrllimited="true" ctrlrange="-90 90"/>
    <motor name="left_knee_joint" joint="left_knee_joint" gear="1" ctrllimited="true" ctrlrange="-150 150"/>
    <motor name="left_ankle_pitch_joint" joint="left_ankle_pitch_joint" gear="1" ctrllimited="true" ctrlrange="-75 75"/>
    <motor name="left_ankle_roll_joint" joint="left_ankle_roll_joint" gear="1" ctrllimited="true" ctrlrange="-75 75"/>

    <motor name="right_hip_pitch_joint" joint="right_hip_pitch_joint" gear="1" ctrllimited="true" ctrlrange="-130 130"/>
    <motor name="right_hip_roll_joint" joint="right_hip_roll_joint" gear="1" ctrllimited="true" ctrlrange="-130 130"/>
    <motor name="right_hip_yaw_joint" joint="right_hip_yaw_joint" gear="1" ctrllimited="true" ctrlrange="-90 90"/>
    <motor name="right_knee_joint" joint="right_knee_joint" gear="1" ctrllimited="true" ctrlrange="-150 150"/>
    <motor name="right_ankle_pitch_joint" joint="right_ankle_pitch_joint" gear="1" ctrllimited="true" ctrlrange="-75 75"/>
    <motor name="right_ankle_roll_joint" joint="right_ankle_roll_joint" gear="1" ctrllimited="true" ctrlrange="-75 75"/>
  </actuator>

     <sensor>
        <framequat     name='orientation' objtype='site' noise='0.001' objname='imu_in_base'/>
        <framepos     name='position' objtype='site' noise='0.001' objname='imu_in_base'/>
        <gyro          name='angular-velocity'    site='imu_in_base' noise='0.005' cutoff='34.9'/>
        <velocimeter   name='linear-velocity'     site='imu_in_base' noise='0.001' cutoff='30'/>
        <accelerometer name='linear-acceleration' site='imu_in_base' noise='0.005' cutoff='157'/>
        <magnetometer  name='magnetometer'        site='imu_in_base'/>
    </sensor>

</mujoco>
